<?xml version="1.0"?>
<robot name="cs63_tesollo">
  
  <!-- Materials -->
  <material name="LightGrey">
    <color rgba="0.7 0.7 0.7 1.0"/>
  </material>

  <material name="silver">
    <color rgba="0.700 0.700 0.700 1.000"/>
  </material>

  <material name="black">
    <color rgba="0.196 0.196 0.196 1.0"/>
  </material>

  <material name="white">
    <color rgba="1.0 1.0 1.0 1.0"/>
  </material>
  
  <!-- Base link -->
  <link name="base_link">
    <visual>
      <origin xyz="0 0 0" rpy="0 0 0"/>
      <geometry>
        <mesh filename="meshes/visual/base.dae"/>
      </geometry>
      <material name="LightGrey"/>
    </visual>
    <collision>
      <origin xyz="0 0 0" rpy="0 0 0"/>
      <geometry>
        <mesh filename="meshes/collision/base.stl"/>
      </geometry>
    </collision>
    <inertial>
      <mass value="0.358193760044688"/>
      <origin xyz="-0.000721181367009438 1.78114684963572e-05 0.0546249293265112" rpy="0 0 0"/>
      <inertia ixx="0.000549739542527148" ixy="8.03741216179988e-08" ixz="-9.14780809458034e-06" 
               iyy="0.000533024165382036" iyz="3.46908903534662e-07" izz="0.000655188839052244"/>
    </inertial>
  </link>
  
  <!-- Shoulder link -->
  <link name="shoulder_link">
    <visual>
      <origin xyz="0 0 0" rpy="0 0 0"/>
      <geometry>
        <mesh filename="meshes/visual/shoulder.dae"/>
      </geometry>
      <material name="LightGrey"/>
    </visual>
    <collision>
      <origin xyz="0 0 0" rpy="0 0 0"/>
      <geometry>
        <mesh filename="meshes/collision/shoulder.stl"/>
      </geometry>
    </collision>
    <inertial>
      <mass value="3.095"/>
      <origin xyz="3.7e-05 -0.0149 -0.0105" rpy="0 0 0"/>
      <inertia ixx="0.007958" ixy="5.734e-06" ixz="3.024e-06" 
               iyy="0.00484" iyz="-1.77e-05" izz="0.006686"/>
    </inertial>
  </link>
  
  <!-- Upperarm link -->
  <link name="upperarm_link">
    <visual>
      <origin xyz="0 0 0" rpy="0 0 0"/>
      <geometry>
        <mesh filename="meshes/visual/upperarm.dae"/>
      </geometry>
      <material name="LightGrey"/>
    </visual>
    <collision>
      <origin xyz="0 0 0" rpy="0 0 0"/>
      <geometry>
        <mesh filename="meshes/collision/upperarm.stl"/>
      </geometry>
    </collision>
    <inertial>
      <mass value="5.073"/>
      <origin xyz="-0.11596 -2.6e-05 0.1148" rpy="0 0 0"/>
      <inertia ixx="0.074168" ixy="-7.5e-06" ixz="-0.065579" 
               iyy="0.21937" iyz="-2.19e-05" izz="0.15104"/>
    </inertial>
  </link>
  
  <!-- Forearm link -->
  <link name="forearm_link">
    <visual>
      <origin xyz="0 0 0" rpy="0 0 0"/>
      <geometry>
        <mesh filename="meshes/visual/forearm.dae"/>
      </geometry>
      <material name="LightGrey"/>
    </visual>
    <collision>
      <origin xyz="0 0 0" rpy="0 0 0"/>
      <geometry>
        <mesh filename="meshes/collision/forearm.stl"/>
      </geometry>
    </collision>
    <inertial>
      <mass value="2.425"/>
      <origin xyz="-0.1542 1.4e-05 0.0238" rpy="0 0 0"/>
      <inertia ixx="0.005082" ixy="-2.7e-06" ixz="-0.0056236" 
               iyy="0.0924207" iyz="-1.726e-06" izz="0.0897559"/>
    </inertial>
  </link>
  
  <!-- Wrist 1 link -->
  <link name="wrist_1_link">
    <visual>
      <origin xyz="0 0 0" rpy="0 0 0"/>
      <geometry>
        <mesh filename="meshes/visual/wrist1.dae"/>
      </geometry>
      <material name="LightGrey"/>
    </visual>
    <collision>
      <origin xyz="0 0 0" rpy="0 0 0"/>
      <geometry>
        <mesh filename="meshes/collision/wrist1.stl"/>
      </geometry>
    </collision>
    <inertial>
      <mass value="1.559"/>
      <origin xyz="1.3e-05 -0.00479 -0.02274" rpy="0 0 0"/>
      <inertia ixx="0.0045009" ixy="1.96e-06" ixz="-2.646e-06" 
               iyy="0.0042164" iyz="-3.58e-07" izz="0.0014538"/>
    </inertial>
  </link>
  
  <!-- Wrist 2 link -->
  <link name="wrist_2_link">
    <visual>
      <origin xyz="0 0 0" rpy="0 0 0"/>
      <geometry>
        <mesh filename="meshes/visual/wrist2.dae"/>
      </geometry>
      <material name="LightGrey"/>
    </visual>
    <collision>
      <origin xyz="0 0 0" rpy="0 0 0"/>
      <geometry>
        <mesh filename="meshes/collision/wrist2.stl"/>
      </geometry>
    </collision>
    <inertial>
      <mass value="1.447"/>
      <origin xyz="-1.4e-05 0.0051 -0.0127" rpy="0 0 0"/>
      <inertia ixx="0.0023787" ixy="1.953e-06" ixz="2.643e-06" 
               iyy="0.0020859" iyz="5.584e-06" izz="0.0013191"/>
    </inertial>
  </link>
  
  <!-- Wrist 3 link -->
  <link name="wrist_3_link">
    <visual>
      <origin xyz="0 0 0" rpy="0 0 0"/>
      <geometry>
        <mesh filename="meshes/visual/wrist3.dae"/>
      </geometry>
      <material name="LightGrey"/>
    </visual>
    <collision>
      <origin xyz="0 0 0" rpy="0 0 0"/>
      <geometry>
        <mesh filename="meshes/collision/wrist3.stl"/>
      </geometry>
    </collision>
    <inertial>
      <mass value="0.5"/>
      <origin xyz="-0.000684 -0.000175 -0.0423" rpy="0 0 0"/>
      <inertia ixx="0.001431" ixy="-2.32e-07" ixz="7.955e-06" 
               iyy="0.0014299" iyz="1.266e-06" izz="0.0003265"/>
    </inertial>
  </link>
  
  <!-- Joint 1: Shoulder Pan -->
  <joint name="shoulder_pan_joint" type="revolute">
    <parent link="base_link"/>
    <child link="shoulder_link"/>
    <origin xyz="0 0 0.153" 
            rpy="0 0 0"/>
    <axis xyz="0 0 1"/>
    <limit lower="-6.283185307179586" upper="6.283185307179586" 
           effort="56.0" velocity="3.141592653589793"/>
    <dynamics damping="0" friction="0"/>
  </joint>
  
  <!-- Joint 2: Shoulder Lift -->
  <joint name="shoulder_lift_joint" type="revolute">
    <parent link="shoulder_link"/>
    <child link="upperarm_link"/>
    <origin xyz="0 0 0" 
            rpy="1.570796326589793 0 0"/>
    <axis xyz="0 0 1"/>
    <limit lower="-6.283185307179586" upper="6.283185307179586" 
           effort="56.0" velocity="3.141592653589793"/>
    <dynamics damping="0" friction="0"/>
  </joint>
  
  <!-- Joint 3: Elbow -->
  <joint name="elbow_joint" type="revolute">
    <parent link="upperarm_link"/>
    <child link="forearm_link"/>
    <origin xyz="-0.27 0 0" 
            rpy="0 0 0"/>
    <axis xyz="0 0 1"/>
    <limit lower="-3.141592653589793" upper="3.141592653589793" 
           effort="28.0" velocity="3.141592653589793"/>
    <dynamics damping="0" friction="0"/>
  </joint>
  
  <!-- Joint 4: Wrist 1 -->
  <joint name="wrist_1_joint" type="revolute">
    <parent link="forearm_link"/>
    <child link="wrist_1_link"/>
    <origin xyz="-0.2575 0 0.1445" 
            rpy="0 0 0"/>
    <axis xyz="0 0 1"/>
    <limit lower="-6.283185307179586" upper="6.283185307179586" 
           effort="12.0" velocity="6.283185307179586"/>
    <dynamics damping="0" friction="0"/>
  </joint>
  
  <!-- Joint 5: Wrist 2 -->
  <joint name="wrist_2_joint" type="revolute">
    <parent link="wrist_1_link"/>
    <child link="wrist_2_link"/>
    <origin xyz="0 -0.0965 0" 
            rpy="1.570796326589793 0 0"/>
    <axis xyz="0 0 1"/>
    <limit lower="-6.283185307179586" upper="6.283185307179586" 
           effort="12.0" velocity="6.283185307179586"/>
    <dynamics damping="0" friction="0"/>
  </joint>
  
  <!-- Joint 6: Wrist 3 -->
  <joint name="wrist_3_joint" type="revolute">
    <parent link="wrist_2_link"/>
    <child link="wrist_3_link"/>
    <origin xyz="0 0.092 0" 
            rpy="-1.570796326589793 0 0"/>
    <axis xyz="0 0 1"/>
    <limit lower="-6.283185307179586" upper="6.283185307179586" 
           effort="12.0" velocity="6.283185307179586"/>
    <dynamics damping="0" friction="0"/>
  </joint>
  
  <!-- Additional frames -->
  <link name="flange">
    <collision>
         <origin xyz="0.0 0.0 0.03" rpy="0 0 0"/>
         <geometry>
            <cylinder radius="0.035" length="0.0448"/>
         </geometry>
      </collision>
  </link>
  <joint name="wrist_3-flange" type="fixed">
    <parent link="wrist_3_link"/>
    <child link="flange"/>
    <origin xyz="0 0 0" rpy="0 0 0"/>
  </joint>

  <!-- Delto gripper base link (merged from delto_base_link_cs63 and delto_base_link) -->
  <link name="delto_base_link">
    <inertial>
      <origin xyz="0.00045499721796859983 -2.051648304165415e-06 -0.05218562175888181" rpy="5.671320207730568e-06 0.0032948722942074404 -0.00044870150924543735"/>
      <mass value="0.370"/>
      <inertia ixx="0.0009935903471030175" iyy="0.000980251548061173" izz="0.0003178199035240808" ixy="0" ixz="0" iyz="0"/>
    </inertial>

    <visual>
      <origin xyz="0.00045499721796859983 -2.051648304165415e-06 -0.05218562175888181" rpy="5.671320207730568e-06 0.0032948722942074404 -0.00044870150924543735"/>
      <geometry>
        <mesh filename="meshes/delto_base_link.stl"/>
      </geometry>
      <material name="black"/>
    </visual>

    <!-- <collision>
      <origin xyz="0.00045499721796859983 -2.051648304165415e-06 -0.05218562175888181" rpy="5.671320207730568e-06 0.0032948722942074404 -0.00044870150924543735"/>
      <geometry>
        <mesh filename="meshes/delto_base_link.stl"/>
      </geometry>
    </collision> -->
    <collision>
        <origin xyz="0.0 0.0 0.0194" rpy="0 0 0"/>
        <geometry>
          <cylinder radius="0.028" length="0.0025"/>
        </geometry>
    </collision>

  </link>

  <joint name="flange-delto_base_link_joint" type="fixed">
    <parent link="flange"/>
    <child link="delto_base_link"/>
    <origin xyz="0.0 0.0 0.11415" rpy="0 0 0"/>
  </joint>

  <!-- Gripper links -->
  <link name="F1_01">
    <inertial>
      <origin xyz="0.0003906 3.121e-08 -0.014" rpy="-0.17662368646091148 -1.9303231388878572e-06 1.5707855116626381"/>
      <mass value="0.061"/>
      <inertia ixx="1.924000000025899e-05" iyy="1.709411627342488e-05" izz="5.9478837263161295e-06" ixy="0" ixz="0" iyz="0"/>
    </inertial>

    <visual>
      <origin xyz="0.0018977016221143523 -1.0017682763976983e-06 -0.022983822146236326" rpy="-0.1443920950720977 1.9855029389503898e-05 1.5709191233325221"/>
      <geometry>
        <mesh filename="meshes/link_01.stl"/>
      </geometry>
      <material name="black"/>
    </visual>
    
    <collision>
      <origin xyz="0.0018977016221143523 -1.0017682763976983e-06 -0.022983822146236326" rpy="-0.1443920950720977 1.9855029389503898e-05 1.5709191233325221"/>
      <geometry>
        <mesh filename="meshes/link_01.stl"/>
      </geometry>
    </collision> 
  </link>

  <link name="F1_02">
    <inertial>
      <origin xyz="0.01 3.444e-06 0.016" rpy="-0.0036890516412144943 0.31688564121750695 -0.0027736178951144786"/>
      <mass value="0.025"/>
      <inertia ixx="7.164797732610912e-06" iyy="6.31301833122199e-06" izz="3.274183936167101e-06" ixy="0" ixz="0" iyz="0"/>
    </inertial>

    <visual>
      <origin xyz="0.010322007813576017 0.000267674195662055 0.013590600703218703" rpy="-0.03118104794815292 0.3757385725887219 -0.024334342208719002"/>
      <geometry>
        <mesh filename="meshes/link_02.stl"/>
      </geometry>
      <material name="black"/>
    </visual>

    <collision>
      <origin xyz="0.010322007813576017 0.000267674195662055 0.013590600703218703" rpy="-0.03118104794815292 0.3757385725887219 -0.024334342208719002"/>
      <geometry>
        <mesh filename="meshes/link_02.stl"/>
      </geometry>
    </collision>
  </link>

  <link name="F1_03">
    <inertial>
      <origin xyz="0.014 -0.0004527 -3.953e-05" rpy="1.5651066808062148 -0.0008576993469346927 1.5562600280492769"/>
      <mass value="0.051"/>
      <inertia ixx="1.6912201686125405e-05" iyy="1.4940271596370447e-05" izz="6.505526717504149e-06" ixy="0" ixz="0" iyz="0"/>
    </inertial>

    <visual>
      <origin xyz="0.019034639558839914 -0.0007611783816217545 0.00015734818842133856" rpy="1.5405533073968862 -0.0023628127138719535 1.5994547590929262"/>
      <geometry>
        <mesh filename="meshes/link_03.stl"/>
      </geometry>
      <material name="black"/>
    </visual>

    <collision>
      <origin xyz="0.019034639558839914 -0.0007611783816217545 0.00015734818842133856" rpy="1.5405533073968862 -0.0023628127138719535 1.5994547590929262"/>
      <geometry>
        <mesh filename="meshes/link_03.stl"/>
      </geometry>
    </collision>
  </link>

  <link name="F1_04">
    <inertial>
      <origin xyz="0.012 -0.0002269 -4.676e-05" rpy="1.5668480451228681 -0.0008686188531681349 1.5829731507939977"/>
      <mass value="0.058"/>
      <inertia ixx="1.0860820276783573e-05" iyy="9.902070548178027e-06" izz="5.330109175038405e-06" ixy="0" ixz="0" iyz="0"/>
    </inertial>

    <visual>
      <origin xyz="0.011992289866897352 -0.0007726988011287212 -5.201111709052532e-06" rpy="1.5745317514920234 0.003601150001683928 1.6650413701206925"/>
      <geometry>
        <mesh filename="meshes/link_04.stl"/>
      </geometry>
      <material name="black"/>
    </visual>

    <collision>
      <origin xyz="0.011992289866897352 -0.0007726988011287212 -5.201111709052532e-06" rpy="1.5745317514920234 0.003601150001683928 1.6650413701206925"/>
      <geometry>
        <mesh filename="meshes/link_04.stl"/>
      </geometry>
    </collision>
  </link>

  <link name="F1_TIP">
    <inertial>
      <origin xyz="0.045 -0.000436 -7.22e-08" rpy="1.5708008179564292 -3.695361794919805e-05 1.5210948927815267"/>
      <mass value="0.013"/>
      <inertia ixx="1.5965708653714455e-06" iyy="1.2999999996018677e-06" izz="9.60129135026688e-07" ixy="0" ixz="0" iyz="0"/>
    </inertial>

    <visual>
      <origin xyz="0.044959448417087294 -0.0004226309811080281 2.3018946871860735e-07" rpy="1.5708745579876908 -1.019986385419891e-05 1.5204133624130758"/>
      <geometry>
        <mesh filename="meshes/link_tip_high.stl"/>
      </geometry>
      <material name="white"/>
    </visual>

    <collision>
      <origin xyz="0.044959448417087294 -0.0004226309811080281 2.3018946871860735e-07" rpy="1.5708745579876908 -1.019986385419891e-05 1.5204133624130758"/>
      <geometry>
        <mesh filename="meshes/link_tip_high.stl"/>
      </geometry>
    </collision>
  </link>

  <link name="F2_01">
    <inertial>
      <origin xyz="0.0003906 3.121e-08 -0.014" rpy="-0.17662368646091148 -1.9303231388878572e-06 1.5707855116626381"/>
      <mass value="0.061"/>
      <inertia ixx="1.924000000025899e-05" iyy="1.709411627342488e-05" izz="5.9478837263161295e-06" ixy="0" ixz="0" iyz="0"/>
    </inertial>

    <visual>
      <origin xyz="0.0018977016221143523 -1.0017682763976983e-06 -0.022983822146236326" rpy="-0.1443920950720977 1.9855029389503898e-05 1.5709191233325221"/>
      <geometry>
        <mesh filename="meshes/link_01.stl"/>
      </geometry>
      <material name="black"/>
    </visual>

    <collision>
      <origin xyz="0.0018977016221143523 -1.0017682763976983e-06 -0.022983822146236326" rpy="-0.1443920950720977 1.9855029389503898e-05 1.5709191233325221"/>
      <geometry>
        <mesh filename="meshes/link_01.stl"/>
      </geometry>
    </collision>
  </link>

  <link name="F2_02">
    <inertial>
      <origin xyz="0.01 3.444e-06 0.016" rpy="-0.0036890516412144943 0.31688564121750695 -0.0027736178951144786"/>
      <mass value="0.025"/>
      <inertia ixx="7.164797732610912e-06" iyy="6.31301833122199e-06" izz="3.274183936167101e-06" ixy="0" ixz="0" iyz="0"/>
    </inertial>

    <visual>
      <origin xyz="0.010322007813576017 0.000267674195662055 0.013590600703218703" rpy="-0.03118104794815292 0.3757385725887219 -0.024334342208719002"/>
      <geometry>
        <mesh filename="meshes/link_02.stl"/>
      </geometry>
      <material name="black"/>
    </visual>

    <collision>
      <origin xyz="0.010322007813576017 0.000267674195662055 0.013590600703218703" rpy="-0.03118104794815292 0.3757385725887219 -0.024334342208719002"/>
      <geometry>
        <mesh filename="meshes/link_02.stl"/>
      </geometry>
    </collision>
  </link>

  <link name="F2_03">
    <inertial>
      <origin xyz="0.014 -0.0004527 -3.953e-05" rpy="1.5651066808062148 -0.0008576993469346927 1.5562600280492769"/>
      <mass value="0.051"/>
      <inertia ixx="1.6912201686125405e-05" iyy="1.4940271596370447e-05" izz="6.505526717504149e-06" ixy="0" ixz="0" iyz="0"/>
    </inertial>

    <visual>
      <origin xyz="0.019034639558839914 -0.0007611783816217545 0.00015734818842133856" rpy="1.5405533073968862 -0.0023628127138719535 1.5994547590929262"/>
      <geometry>
        <mesh filename="meshes/link_03.stl"/>
      </geometry>
      <material name="black"/>
    </visual>

    <collision>
      <origin xyz="0.019034639558839914 -0.0007611783816217545 0.00015734818842133856" rpy="1.5405533073968862 -0.0023628127138719535 1.5994547590929262"/>
      <geometry>
        <mesh filename="meshes/link_03.stl"/>
      </geometry>
    </collision>
  </link>

  <link name="F2_04">
    <inertial>
      <origin xyz="0.012 -0.0002269 -4.676e-05" rpy="1.5668480451228681 -0.0008686188531681349 1.5829731507939977"/>
      <mass value="0.058"/>
      <inertia ixx="1.0860820276783573e-05" iyy="9.902070548178027e-06" izz="5.330109175038405e-06" ixy="0" ixz="0" iyz="0"/>
    </inertial>

    <visual>
      <origin xyz="0.011992289866897352 -0.0007726988011287212 -5.201111709052532e-06" rpy="1.5745317514920234 0.003601150001683928 1.6650413701206925"/>
      <geometry>
        <mesh filename="meshes/link_04.stl"/>
      </geometry>
      <material name="black"/>
    </visual>

    <collision>
      <origin xyz="0.011992289866897352 -0.0007726988011287212 -5.201111709052532e-06" rpy="1.5745317514920234 0.003601150001683928 1.6650413701206925"/>
      <geometry>
        <mesh filename="meshes/link_04.stl"/>
      </geometry>
    </collision>
  </link>

  <link name="F2_TIP">
    <inertial>
      <origin xyz="0.045 -0.000436 -7.22e-08" rpy="1.5708008179564292 -3.695361794919805e-05 1.5210948927815267"/>
      <mass value="0.013"/>
      <inertia ixx="1.5965708653714455e-06" iyy="1.2999999996018677e-06" izz="9.60129135026688e-07" ixy="0" ixz="0" iyz="0"/>
    </inertial>

    <visual>
      <origin xyz="0.044959448417087294 -0.0004226309811080281 2.3018946871860735e-07" rpy="1.5708745579876908 -1.019986385419891e-05 1.5204133624130758"/>
      <geometry>
        <mesh filename="meshes/link_tip_high.stl"/>
      </geometry>
      <material name="white"/>
    </visual>

    <collision>
      <origin xyz="0.044959448417087294 -0.0004226309811080281 2.3018946871860735e-07" rpy="1.5708745579876908 -1.019986385419891e-05 1.5204133624130758"/>
      <geometry>
        <mesh filename="meshes/link_tip_high.stl"/>
      </geometry>
    </collision>
  </link>

  <link name="F3_01">
    <inertial>
      <origin xyz="0.0003906 3.121e-08 -0.014" rpy="-0.17662368646091148 -1.9303231388878572e-06 1.5707855116626381"/>
      <mass value="0.061"/>
      <inertia ixx="1.924000000025899e-05" iyy="1.709411627342488e-05" izz="5.9478837263161295e-06" ixy="0" ixz="0" iyz="0"/>
    </inertial>

    <visual>
      <origin xyz="0.0018977016221143523 -1.0017682763976983e-06 -0.022983822146236326" rpy="-0.1443920950720977 1.9855029389503898e-05 1.5709191233325221"/>
      <geometry>
        <mesh filename="meshes/link_01.stl"/>
      </geometry>
      <material name="black"/>
    </visual>

    <collision>
      <origin xyz="0.0018977016221143523 -1.0017682763976983e-06 -0.022983822146236326" rpy="-0.1443920950720977 1.9855029389503898e-05 1.5709191233325221"/>
      <geometry>
        <mesh filename="meshes/link_01.stl"/>
      </geometry>
    </collision>
  </link>
  
  <link name="F3_02">
    <inertial>
      <origin xyz="0.01 3.444e-06 0.016" rpy="-0.0036890516412144943 0.31688564121750695 -0.0027736178951144786"/>
      <mass value="0.025"/>
      <inertia ixx="7.164797732610912e-06" iyy="6.31301833122199e-06" izz="3.274183936167101e-06" ixy="0" ixz="0" iyz="0"/>
    </inertial>
    <visual>
      <origin xyz="0.010322007813576017 0.000267674195662055 0.013590600703218703" rpy="-0.03118104794815292 0.3757385725887219 -0.024334342208719002"/>
      <geometry>
        <mesh filename="meshes/link_02.stl"/>
      </geometry>
      <material name="black"/>
    </visual>

    <collision>
      <origin xyz="0.010322007813576017 0.000267674195662055 0.013590600703218703" rpy="-0.03118104794815292 0.3757385725887219 -0.024334342208719002"/>
      <geometry>
        <mesh filename="meshes/link_02.stl"/>
      </geometry>
    </collision>
  </link>

  <link name="F3_03">
    <inertial>
      <origin xyz="0.014 -0.0004527 -3.953e-05" rpy="1.5651066808062148 -0.0008576993469346927 1.5562600280492769"/>
      <mass value="0.051"/>
      <inertia ixx="1.6912201686125405e-05" iyy="1.4940271596370447e-05" izz="6.505526717504149e-06" ixy="0" ixz="0" iyz="0"/>
    </inertial>
    <visual>
      <origin xyz="0.019034639558839914 -0.0007611783816217545 0.00015734818842133856" rpy="1.5405533073968862 -0.0023628127138719535 1.5994547590929262"/>
      <geometry>
        <mesh filename="meshes/link_03.stl"/>
      </geometry>
      <material name="black"/>
    </visual>

    <collision>
      <origin xyz="0.019034639558839914 -0.0007611783816217545 0.00015734818842133856" rpy="1.5405533073968862 -0.0023628127138719535 1.5994547590929262"/>
      <geometry>
        <mesh filename="meshes/link_03.stl"/>
      </geometry>
    </collision>
  </link>

  <link name="F3_04">
    <inertial>
      <origin xyz="0.012 -0.0002269 -4.676e-05" rpy="1.5668480451228681 -0.0008686188531681349 1.5829731507939977"/>
      <mass value="0.058"/>
      <inertia ixx="1.0860820276783573e-05" iyy="9.902070548178027e-06" izz="5.330109175038405e-06" ixy="0" ixz="0" iyz="0"/>
    </inertial>
    <visual>
      <origin xyz="0.011992289866897352 -0.0007726988011287212 -5.201111709052532e-06" rpy="1.5745317514920234 0.003601150001683928 1.6650413701206925"/>
      <geometry>
        <mesh filename="meshes/link_04.stl"/>
      </geometry>
      <material name="black"/>
    </visual>

    <collision>
      <origin xyz="0.011992289866897352 -0.0007726988011287212 -5.201111709052532e-06" rpy="1.5745317514920234 0.003601150001683928 1.6650413701206925"/>
      <geometry>
        <mesh filename="meshes/link_04.stl"/>
      </geometry>
    </collision>
  </link>

  <link name="F3_TIP">
    <inertial>
      <origin xyz="0.045 -0.000436 -7.22e-08" rpy="1.5708008179564292 -3.695361794919805e-05 1.5210948927815267"/>
      <mass value="0.013"/>
      <inertia ixx="1.5965708653714455e-06" iyy="1.2999999996018677e-06" izz="9.60129135026688e-07" ixy="0" ixz="0" iyz="0"/>
    </inertial>
    <visual>
      <origin xyz="0.044959448417087294 -0.0004226309811080281 2.3018946871860735e-07" rpy="1.5708745579876908 -1.019986385419891e-05 1.5204133624130758"/>
      <geometry>
        <mesh filename="meshes/link_tip_high.stl"/>
      </geometry>
      <material name="white"/>
    </visual>

    <collision>
      <origin xyz="0.044959448417087294 -0.0004226309811080281 2.3018946871860735e-07" rpy="1.5708745579876908 -1.019986385419891e-05 1.5204133624130758"/>
      <geometry>
        <mesh filename="meshes/link_tip_high.stl"/>
      </geometry>
    </collision>
  </link>

  <!-- Gripper joints -->
  <joint name="F1M1" type="revolute">
    <origin xyz="0.0265 0.0 0.0" rpy="0 0 0"/>
    <parent link="delto_base_link"/>
    <child link="F1_01"/>
    <axis xyz="0.0 0.0 1.0"/>
    <limit effort="10.0" velocity="5.0" lower="-1.0472" upper="1.0472" />
    <dynamics damping="1.1" friction="1.1"/>
  </joint>

  <joint name="F1M2" type="revolute">
    <origin xyz="0.0 0.0 0.0" rpy="-3.1415926207728213 -1.570796290294655 0.0"/>
    <parent link="F1_01"/>
    <child link="F1_02"/>
    <axis xyz="0.0 0.0 1.0"/>
    <limit effort="10.0" velocity="5.0" lower="-1.76278" upper="1.76278" />
    <dynamics damping="1.1" friction="1.1"/>
  </joint>

  <joint name="F1M3" type="revolute">
    <origin xyz="0.02022 0.0 0.03136" rpy="-1.5707963295583207 -1.5707963267948966 0.0"/>
    <parent link="F1_02"/>
    <child link="F1_03"/>
    <axis xyz="0.0 0.0 1.0"/>
    <limit effort="10.0" velocity="5.0" lower="-0.15708" upper="2.53073" />
    <dynamics damping="1.1" friction="1.1"/>
  </joint>

  <joint name="F1M4" type="revolute">
    <origin xyz="0.0434 0.0 0.0" rpy="0 0 0"/>
    <parent link="F1_03"/>
    <child link="F1_04"/>
    <axis xyz="0.0 0.0 1.0"/>
    <limit effort="10.0" velocity="5.0" lower="-0.226893" upper="2.02458"/>
    <dynamics damping="1.1" friction="1.1"/>
  </joint>

  <joint name="TIP1" type="fixed">
    <origin xyz="0.0 0.0 0.0" rpy="0 0 0"/>
    <parent link="F1_04"/>
    <child link="F1_TIP"/>
  </joint>

  <!-- FINGER 2-->
  <joint name="F2M1" type="revolute">
    <origin xyz="-0.01334 0.023 0.0" rpy="0 0 -3.14"/>
    <parent link="delto_base_link"/>
    <child link="F2_01"/>
    <axis xyz="0.0 0.0 1.0"/>
    <limit effort="10.0" velocity="5.0" lower="-1.91986" upper="0.139626" />
    <dynamics damping="1.1" friction="1.1"/>
  </joint>

  <joint name="F2M2" type="revolute">
    <origin xyz="0.0 0.0 0.0" rpy="-3.14 -1.57 0"/>
    <parent link="F2_01"/>
    <child link="F2_02"/>
    <axis xyz="0.0 0.0 1.0"/>
    <limit effort="10.0" velocity="5.0" lower="-1.76278" upper="1.76278" />
    <dynamics damping="1.1" friction="1.1"/>
  </joint>

  <joint name="F2M3" type="revolute">
    <origin xyz="0.02022 0.0 0.03136" rpy="-1.57 -1.57 0"/>
    <parent link="F2_02"/>
    <child link="F2_03"/>
    <axis xyz="0.0 0.0 1.0"/>
    <limit effort="10.0" velocity="5.0" lower="-0.15708" upper="2.53073" />
    <dynamics damping="1.1" friction="1.1"/>
  </joint>

  <joint name="F2M4" type="revolute">
    <origin xyz="0.0434 0.0 0.0" rpy="0 0 0"/>
    <parent link="F2_03"/>
    <child link="F2_04"/>
    <axis xyz="0.0 0.0 1.0"/>
    <limit effort="10.0" velocity="5.0" lower="-0.226893" upper="2.02458"/>
    <dynamics damping="1.1" friction="1.1"/>
  </joint>

  <joint name="TIP2" type="fixed">
    <origin xyz="0.0 0.0 0.0" rpy="0 0 0"/>
    <parent link="F2_04"/>
    <child link="F2_TIP"/>
  </joint>

  <!-- FINGER 3-->   
  <joint name="F3M1" type="revolute">
    <origin xyz="-0.01334 -0.023 0.0" rpy="0 0 -3.14"/>
    <parent link="delto_base_link"/>
    <child link="F3_01"/>
    <axis xyz="0.0 0.0 1.0"/>
    <limit effort="10.0" velocity="5.0" lower="-0.0872665" upper="2.00713" />
    <dynamics damping="1.1" friction="1.1"/>
  </joint>

  <joint name="F3M2" type="revolute">
    <origin xyz="0.0 0.0 0.0" rpy="-3.14 -1.57 0"/>
    <parent link="F3_01"/>
    <child link="F3_02"/>
    <axis xyz="0.0 0.0 1.0"/>
    <limit effort="10.0" velocity="5.0" lower="-1.76278" upper="1.76278" />
    <dynamics damping="1.1" friction="1.1"/>
  </joint>

  <joint name="F3M3" type="revolute">
    <origin xyz="0.02022 0.0 0.03136" rpy="-1.57 -1.57 0"/>
    <parent link="F3_02"/>
    <child link="F3_03"/>
    <axis xyz="0.0 0.0 1.0"/>
    <limit effort="10.0" velocity="5.0" lower="-0.15708" upper="2.53073" />
    <dynamics damping="1.1" friction="1.1"/>
  </joint>

  <joint name="F3M4" type="revolute">
    <origin xyz="0.0434 0.0 0.0" rpy="0 0 0"/>
    <parent link="F3_03"/>
    <child link="F3_04"/>
    <axis xyz="0.0 0.0 1.0"/>
    <limit effort="10.0" velocity="5.0" lower="-0.226893" upper="2.02458"/>
    <dynamics damping="1.1" friction="1.1"/>
  </joint>

  <joint name="TIP3" type="fixed">
    <origin xyz="0.0 0.0 0.0" rpy="0 0 0"/>
    <parent link="F3_04"/>
    <child link="F3_TIP"/>
  </joint>

  <!-- Palm control frame for fabric (fixed to gripper base) -->
  <link name="palm_link"/>
  <joint name="delto_base-palm_link" type="fixed">
    <parent link="delto_base_link"/>
    <child link="palm_link"/>
    <origin xyz="0 0 0.02065" rpy="0 0 0"/>
  </joint>

</robot>

